Workbook

Sheet Read_Me
A1: HSWRMS — BÁO CÁO ĐỐI SOÁT BẰNG CHỨNG & ĐÁNH GIÁ ĐÓNG GÓP (TARGETED CORRECTION)
A2: Hệ thống Quản lý Khu Nghỉ dưỡng Trị liệu HeavenStay Wellness Resort Management System (ISP392_IS2005_G1)
A4: 1. MỤC ĐÍCH & PHẠM VI WORKBOOK NÀY
A5: Workbook này là sản phẩm đối soát và gia cố bằng chứng, đã được rà soát và hiệu chỉnh mục tiêu (Targeted Correction) theo các chuẩn mực kiểm toán nghiêm ngặt.
A6: Tất cả dữ liệu được xác thực đa chiều giữa: Kế hoạch WBS gốc (Task_Project_G1_IS2005.xlsx), nhật ký tích hợp Git Phase 117-118, mã nguồn thực tế và kết quả kiểm thử.
A8: 2. CÁC NỘI DUNG HIỆU CHỈNH MỤC TIÊU ĐÃ HOÀN TẤT
A9: - Tính điểm trực tiếp từ 11 tiêu chí: Điểm tổng kết 6 sinh viên được tính trực tiếp từ 11 tiêu chí và trọng số chuẩn (=SUMPRODUCT(C2:C12, E2:E12)) thay vì phụ thuộc vào làm tròn nhóm.
A10: - Đồng bộ điểm số 100%: Lê Đức Hoàng: 9.17 | Nguyễn Gia Đạt: 8.86 | Nguyễn Tất Đạt: 9.84 | Vũ Phương Thảo: 9.24 | Tăng Xuân Hòa: 9.09 | Phạm Thành Vinh: 8.94 (TB: 9.19).
A11: - Làm rõ 180 tác vụ WBS vs 181 dòng Excel: 180 dòng WBS nghiệp vụ (dòng 4-183) + 1 dòng ghi chú thời hạn thi cử (dòng 185: NOTE) = 181 dòng trong bảng đối soát.
A12: - Minh bạch kiểm thử 536 bài: 526 pass, 10 skip (H2 MSSQLServer mode); chênh lệch 10 bài giữa chi tiết phân hệ (516 pass) và tổng thể (526 pass) được ghi nhận là UNRESOLVED_BREAKDOWN_VARIANCE không tự tạo số liệu.
A13: - Khôi phục 100% MSSV: Khôi phục đầy đủ 6 MSSV chính thức từ bảng kế hoạch gốc; chuẩn hóa họ Tăng / Phạm kèm alias ghi nhận Trần / Phan; tách biệt hoàn toàn Giảng viên.
A14: - Ghi chú công thức: Công thức Excel được viết dạng tiêu chuẩn; phần mềm bảng tính (Excel/Calc/Sheets) sẽ tự động đánh giá khi mở tệp. Nếu đọc qua openpyxl(data_only=True) trước khi mở Excel, giá trị công thức chưa cache sẽ trả về None.
A16: 3. DANH MỤC 14 TRANG TÍNH (SHEETS)
A17: Sheet 01: Read_Me | B17: Trang hướng dẫn, mục đích, phạm vi, giải trình hiệu chỉnh mục tiêu và lưu ý công thức.
A18: Sheet 02: Source_Manifest | B18: Bảng kiểm kê 18 tệp nguồn, kích thước, số dòng và mã băm SHA-256 bất biến.
A19: Sheet 03: Executive_Summary | B19: Tóm tắt điều hành dự án: nhân sự, nhánh Git, chỉ số kiểm thử, CSDL và các rủi ro tồn đọng.
A20: Sheet 04: Member_Reconciliation | B20: Bảng đối soát danh tính 6 sinh viên và 1 giảng viên với đầy đủ MSSV và bằng chứng.
A21: Sheet 05: Task_Assignment | B21: Đối soát 180 tác vụ WBS + 1 dòng footnote dòng 185; phân tách trạng thái và đánh giá hoàn thành.
A22: Sheet 06: Contribution_Log | B22: Nhật ký 44 đóng góp kỹ thuật với trạng thái xác minh và độ tin cậy được hiệu chỉnh.
A23: Sheet 07: Module_Completeness | B23: Bảng kiểm kê độ hoàn thiện 49 cấu phần kỹ thuật (tương ứng 27 Use Case nghiệp vụ).
A24: Sheet 08: Test_Evidence | B24: Bằng chứng kiểm thử; ghi nhận rõ tổng 536 và khoảng chênh lệch UNRESOLVED_BREAKDOWN_VARIANCE.
A25: Sheet 09: Gap_Register | B25: Sổ theo dõi 8 khoảng trống kỹ thuật (GAP-01 đến GAP-08) cần hoàn thiện trước go-live.
A26: Sheet 10: Scoring_Rubric | B26: Khung tiêu chí đánh giá năng lực 11 tiêu chí (TC-01 đến TC-11) với tổng trọng số 100%.
A27: Sheet 11: Member_Scorecard | B27: Bảng điểm tổng hợp của 6 sinh viên tính bằng công thức SUMPRODUCT trực tiếp từ 11 tiêu chí.
A28: Sheet 12: Conflict_Register | B28: Sổ ghi nhận chi tiết các bất đồng dữ liệu lịch sử và giải pháp chuẩn hóa.
... A30: Sheet 14: Change_Log | B30: Nhật ký các thay đổi trọng yếu so với tài liệu audit ban đầu (Correction Log).

Sheet Source_Manifest
A1: File_ID | B1: Relative_Path | C1: File_Type | D1: File_Size_Bytes | E1: Line_Count | F1: Sheet_Info | G1: SHA256_Hash | H1: Authority_Level | I1: Description
A2: SRC-01 | B2: 06_Reports/audit-output/01_Executive_Summary.csv | C2: Audit CSV | D2: 3998 | E2: 17 | F2: N/A | G2: 7b6cfc7927dfb9da226c3e76545a0483e6bf176ef14e4bb5901cfebe27865b15 | H2: DERIVED_AUDIT_EVIDENCE | I2: Original executive summary of module integration status
A3: SRC-02 | B3: 06_Reports/audit-output/02_Member_Summary.csv | C3: Audit CSV | D3: 5270 | E3: 9 | F3: N/A | G3: 45e068882c4cae903ad2cc8821e328721e4469c864207f4c892e8afd2c2383ae | H3: DERIVED_AUDIT_EVIDENCE | I3: Original per-member evaluation and contribution summary
A4: SRC-03 | B4: 06_Reports/audit-output/03_Contribution_Log.csv | C4: Audit CSV | D4: 15285 | E4: 46 | F4: N/A | G4: 9aafd197a99821df3d5d7da2498a743536b17c41e9d2ee567b87fe08cf2c6213 | H4: DERIVED_AUDIT_EVIDENCE | I4: Original granular 44 contribution records
A5: SRC-04 | B5: 06_Reports/audit-output/04_Module_Completeness.csv | C5: Audit CSV | D5: 15447 | E5: 51 | F5: N/A | G5: 7f7376ade69622769d6cf72ea50575aa3269fb36344375ed79102b6d9d7f908a | H5: DERIVED_AUDIT_EVIDENCE | I5: Original 49 technical feature completeness records across M1-M6 + INFRA
A6: SRC-05 | B6: 06_Reports/audit-output/05_Branch_Integration.csv | C6: Audit CSV | D6: 3708 | E6: 10 | F6: N/A | G6: 2200a0f0e0d143964b079864ea424129cb8ce910c07503567fdfbf146fdcaf1a | H6: DERIVED_AUDIT_EVIDENCE | I6: Original git branch integration tracking
A7: SRC-06 | B7: 06_Reports/audit-output/06_Test_Evidence.csv | C7: Audit CSV | D7: 3623 | E7: 14 | F7: N/A | G7: f348d52a67567f161e666b68ec3e83b90ea663be0beb787663b181a7a00898d0 | H7: DERIVED_AUDIT_EVIDENCE | I7: Original 12 test execution and evidence records
A8: SRC-07 | B8: 06_Reports/audit-output/07_Gap_Register.csv | C8: Audit CSV | D8: 3898 | E8: 10 | F8: N/A | G8: 274b1db692c15b72a2b0c76bffea7dda3d7f92851538a34ac74e056c900afe92 | H8: DERIVED_AUDIT_EVIDENCE | I8: Original 8 technical gaps and defect risks
A9: SRC-08 | B9: 06_Reports/audit-output/08_Action_Plan.csv | C9: Audit CSV | D9: 2488 | E9: 10 | F9: N/A | G9: 5acb9d4473e25633c0f57e0b3022798f94729f03c6aff070437cee689b17be29 | H9: DERIVED_AUDIT_EVIDENCE | I9: Original 8 post-merge remediation action items
A10: SRC-09 | B10: 06_Reports/audit-output/09_Evidence_Index.csv | C10: Audit CSV | D10: 8457 | E10: 35 | F10: N/A | G10: 3bc61b1ce9e36750200a63c6d95440b5f36ea212ee960dfd693b24e8cddd4b74 | H10: DERIVED_AUDIT_EVIDENCE | I10: Original index of 35 evidence artifacts
A11: SRC-10 | B11: 06_Reports/audit-output/10_Identity_Mapping.csv | C11: Audit CSV | D11: 1899 | E11: 9 | F11: N/A | G11: 984b0caf8679ddd53579fda34d1f8c03a1f8a99d483bee0554585b859418f1ed | H11: DERIVED_AUDIT_EVIDENCE | I11: Original git alias to human identity mapping (had 3 UNKNOWN Student IDs)
A12: SRC-11 | B12: 06_Reports/audit-output/HSWRMS_BAO_CAO_TONG_KET_DU_AN.md | C12: Audit Report | D12: 51685 | E12: 254 | F12: N/A | G12: 9eb5c14406e0748b720818cf306914568b8442d9a0b812a5f2914345d31c847c | H12: DERIVED_AUDIT_EVIDENCE | I12: Comprehensive Vietnamese technical project audit report
... A19: SRC-18 | B19: 06_Reports/PHASE_5.8.3.117-5.8.3.118_FULL_TEAM_MERGE_HISTORY.txt | C19: Merge History | D19: 57084 | E19: 878 | F19: N/A | G19: 369c5988f80535f7fb0b2398c47984adbff8a9d553c4433027eeed602c753ed9 | H19: PRIMARY_GIT_LOG | I19: Detailed git integration and conflict resolution log (Phase 117-118)

Sheet Executive_Summary
A1: HSWRMS — BÁO CÁO TỔNG QUAN TÌNH TRẠNG DỰ ÁN SAU TÍCH HỢP M1-M6
A3: Hạng mục đánh giá | B3: Chỉ số định lượng | C3: Trạng thái xác minh | D3: Ghi chú & Giới hạn bằng chứng
A4: Tổng số thành viên sinh viên | B4: 6 | C4: VERIFIED | D4: Khôi phục 100% đầy đủ 6 MSSV chính thức từ bảng phân công gốc
A5: Giảng viên hướng dẫn môn học | B5: 1 | C5: VERIFIED | D5: Thầy Nguyễn Cường Mạnh (manhnc5@fe.edu.vn) - Tách riêng khỏi bảng điểm
A6: Số nhánh Git tính năng đóng góp | B6: 8 | C6: VERIFIED | D6: DucHoangM1, dat-nguyen-gia, NTDatZB, thao-product, XH, XH4, vinhpt, vinhpt1
A7: Nhánh tích hợp tổng thể | B7: feature/hswrms-m1-m6-integration | C7: VERIFIED | D7: Hợp nhất thành công toàn bộ mã nguồn của 6 thành viên
A8: Use Case nghiệp vụ cốt lõi (SRS) | B8: 27 | C8: VERIFIED | D8: 27 Luồng nghiệp vụ chính theo yêu cầu người dùng (M1-M6)
A9: Cấu phần kỹ thuật chi tiết | B9: 49 | C9: VERIFIED | D9: 43 cấu phần module + 6 cấu phần hạ tầng chia sẻ (Shared Infrastructure)
A10: Tác vụ WBS nghiệp vụ trong kế hoạch | B10: 180 | C10: VERIFIED_IN_PLAN | D10: 180 tác vụ WBS (dòng 4-183); dòng 185 là ghi chú thời hạn thi cử (NOTE)
A11: Tổng số bài kiểm thử Backend | B11: 536 | C11: REPORTED_IN_PHASE_LOGS | D11: 526 passed, 0 failed, 10 skipped (Thực thi trên H2 MSSQLServer mode)
A12: Độ lệch phân rã kiểm thử chi tiết | B12: 10 | C12: UNRESOLVED_BREAKDOWN_VARIANCE | D12: Chi tiết M1-M6 (274) + Shared (242) = 516 pass; chênh lệch 10 pass so với tổng 526
A13: Kiểm thử trên SQL Server thật | B13: 10 | C13: SKIPPED_BY_DESIGN | D13: Bỏ qua an toàn để bảo vệ database HSWRMS_TEST ID 45
A14: Biên dịch Frontend TypeScript | B14: 2728 | C14: REPORTED_IN_BUILD_LOGS | D14: 2728 module TSX/TS build thành công trong 997ms với Vite v8.3.4
A15: Tĩnh phân tích Frontend Oxlint | B15: 216 | C15: REPORTED_IN_LINT_LOGS | D15: 216 tệp mã nguồn sạch 100%, 0 lỗi, 10 warning không chặn
A16: Điểm đánh giá năng lực trung bình nhóm | B16: 9.19 | C16: RECALCULATED_DIRECT_11_CRIT | D16: Tính trực tiếp từ 11 tiêu chí rubric (Thang 10; Xếp loại Xuất sắc)
A17: Số khoảng trống kỹ thuật tồn đọng | B17: 8 | C17: OPEN | D17: GAP-01 đến GAP-08 đang mở (chờ staging secrets, OAuth, VNPay IPN)
A18: Đột biến cơ sở dữ liệu thật | B18: 0 | C18: VERIFIED_ZERO_MUTATION | D18: Không can thiệp, không migration, không thay đổi CSDL theo quy tắc an toàn

Sheet Member_Reconciliation
A1: Person_ID | B1: Name_As_Recorded | C1: Canonical_Name | D1: Student_ID | E1: Git_Author_Name | F1: Git_Email | G1: Assigned_Module | H1: Identity_Evidence | I1: Verification_Status | J1: Confidence | K1: Unresolved_Questions
A2: MEM-01 | B2: Lê Đức Hoàng (Excel/Doc); Le Duc Hoang (Git) | C2: Lê Đức Hoàng | D2: HE204568 | E2: Le Duc Hoang | F2: leduchoang0946347814@gmail.com | G2: M1 - Identity & Access | H2: Task_Project_G1_IS2005.xlsx ('Đánh giá thành viên' row 9); Git branch DucHoangM1; WBS PIC 'Đức Hoàng' | I2: VERIFIED | J2: HIGH | K2: Previously recorded as UNKNOWN in original 10_Identity_Mapping.csv; resolved via official planning roster.
A3: MEM-02 | B3: Nguyễn Gia Đạt (Excel/Doc); Datnghe181035 (Git) | C3: Nguyễn Gia Đạt | D3: HE181035 | E3: Datnghe181035 | F3: datnghe181035@fpt.edu.vn | G3: M2 - Booking & Reservation | H3: Task_Project_G1_IS2005.xlsx ('Đánh giá thành viên' row 5); Git branch dat-nguyen-gia; WBS PIC 'Gia Đạt' | I3: VERIFIED | J3: HIGH | K3: None. Fully matched across all planning and Git sources.
A4: MEM-03 | B4: Nguyễn Tất Đạt (Excel/Doc); DZB1509 / Nguyen Tat Dat / datnthe181883 (Git) | C4: Nguyễn Tất Đạt | D4: HE181883 | E4: DZB1509; Nguyen Tat Dat (K18 HL); Nguyen_Tat_Dat; datnthe181883 | F4: datnthe181883@fpt.edu.vn; nguyentatdat150904@gmail.com | G4: M3 - Spa & Shared Infrastructure (Technical Lead / Integrator) | H4: Task_Project_G1_IS2005.xlsx ('Đánh giá thành viên' row 6); Git branch NTDatZB; Lead Integrator in all phase logs | I4: VERIFIED | J4: HIGH | K4: Four Git author identities mapped to one human student (Tech Lead).
A5: MEM-04 | B5: Vũ Phương Thảo (Excel/Doc); Thao Vu (Git) | C5: Vũ Phương Thảo | D5: HE204054 | E5: Thao Vu | F5: tvu7092@gmail.com | G5: M4 - Food & Beverage | H5: Task_Project_G1_IS2005.xlsx ('Đánh giá thành viên' row 8); Git branch thao-product; WBS PIC 'Phương Thảo' | I5: VERIFIED | J5: HIGH | K5: Previously recorded as UNKNOWN in original 10_Identity_Mapping.csv; resolved via official planning roster.
A6: MEM-05 | B6: Tăng Xuân Hòa (Planning roster); Trần Xuân Hòa (Earlier reports/notes); hoatxhe180798 (Git) | C6: Tăng Xuân Hòa | D6: HE180798 | E6: hoatxhe180798 | F6: hoatxhe180798@fpt.edu.vn | G6: M5 - Billing & Checkout | H6: Task_Project_G1_IS2005.xlsx ('Đánh giá thành viên' row 4); Git branches XH/XH4; FPT email hoatxhe180798 | I6: VERIFIED | J6: HIGH | K6: Surname discrepancy: 'Tăng' in official planning sheet vs 'Trần' in earlier audit reports. Both refer to HE180798. Canonical: Tăng Xuân Hòa; Alias: Trần Xuân Hòa.
A7: MEM-06 | B7: Phạm Thành Vinh (Planning roster); Phan Thành Vinh (Earlier reports/notes); pthanhvinh26112004 (Git) | C7: Phạm Thành Vinh | D7: HE186593 | E7: pthanhvinh26112004 | F7: pthanhvinh26112004@gmail.com | G7: M6 - Admin & Governance | H7: Task_Project_G1_IS2005.xlsx ('Đánh giá thành viên' row 7); Git branches vinhpt/vinhpt1; WBS PIC 'Thành Vinh' | I7: VERIFIED | J7: HIGH | K7: Surname discrepancy: 'Phạm' in official planning sheet vs 'Phan' in earlier audit reports. Both refer to HE186593. Canonical: Phạm Thành Vinh; Alias: Phan Thành Vinh.
A8: MEM-07 | B8: Nguyễn Cường Mạnh (Git/GitLab) | C8: Nguyễn Cường Mạnh | D8: LECTURER | E8: Nguyen Cuong Manh | F8: manhnc5@fe.edu.vn | G8: Course Governance & Supervision | H8: Git commit 1bc054b; GitLab namespace manhnc2; FPT Education staff email (@fe.edu.vn) | I8: VERIFIED | J8: HIGH | K8: Course instructor / project supervisor. Excluded from student contribution scoring and task averages.

Sheet Task_Assignment
A1: Task_Row | B1: WBS_ID | C1: Task_Name | D1: Planning_PIC_Raw | E1: Canonical_Person_ID | F1: Canonical_Person_Name | G1: Module | H1: Complexity | I1: Planning_Status | J1: Candidate_Git_Evidence | K1: Implementation_Evidence | L1: Test_Evidence | M1: Reconciliation_Relationship | N1: Evidence_Based_Completion_Assessment | O1: Audit_Conclusion | P1: Provenance_Reference
A2: 4 | B2: 1 | C2: Project Initiating | D2: UNASSIGNED | E2: UNASSIGNED | F2: Unassigned / Milestone Header | G2: Cross-Module | H2: Unspecified | I2: Done | J2: N/A (Milestone/Section Grouping Container) | K2: Organizational milestone or phase umbrella header | L2: N/A | M2: UNASSIGNED | N2: NOT_ASSESSABLE | O2: Milestone structure verified in planning baseline | P2: Official Plan Row 4 (Task_Project_G1_IS2005.xlsx)
A3: 5 | B3: 1.1 | C3: Project Planning + PM Plan | D3: Tất Đạt | E3: MEM-03 | F3: Nguyễn Tất Đạt | G3: M3 - Spa & Shared Infrastructure | H3: Medium | I3: Done | J3: Branch NTDatZB (102 commits); merge commits 602c6f8, 0f257ad, 6ff5b9a, 39b086f, 9668586, 1f7ebc1 | K3: SpaTreatmentController, SpaBookingService, CustomerStayPort, SecurityConfig, Design Tokens | L3: 24 M3 tests + 252 shared infra tests (242 passed, 10 skipped live DB) | M3: MATCHED | N3: COMPLETED_VERIFIED | O3: Technical leadership, shared infrastructure, and spa operations verified | P3: Official Plan Row 5 (Task_Project_G1_IS2005.xlsx)
A4: 6 | B4: 1.2 | C4: Setup GitLab (6 module branches + shared core) | D4: Tất Đạt | E4: MEM-03 | F4: Nguyễn Tất Đạt | G4: M3 - Spa & Shared Infrastructure | H4: Simple | I4: Done | J4: Branch NTDatZB (102 commits); merge commits 602c6f8, 0f257ad, 6ff5b9a, 39b086f, 9668586, 1f7ebc1 | K4: SpaTreatmentController, SpaBookingService, CustomerStayPort, SecurityConfig, Design Tokens | L4: 24 M3 tests + 252 shared infra tests (242 passed, 10 skipped live DB) | M4: MATCHED | N4: COMPLETED_VERIFIED | O4: Technical leadership, shared infrastructure, and spa operations verified | P4: Official Plan Row 6 (Task_Project_G1_IS2005.xlsx)
A5: 7 | B5: 1.3 | C5: Meeting: Clarify + Business Rules | D5: Gia Đạt | E5: MEM-02 | F5: Nguyễn Gia Đạt | G5: M2 - Booking & Reservation | H5: Medium | I5: Done | J5: Branch dat-nguyen-gia (8 commits); commit 4bd4ecd (3417 lines); merged in 0f257ad | K5: RetreatPackageController, ReceptionistOperationController, BookingController, VNPayClient | L5: 34 backend tests in M2 (ReceptionistOperationServiceTest) | M5: MATCHED | N5: COMPLETED_VERIFIED | O5: Core workflow verified in code; live VNPay IPN webhook callbacks require staging (GAP-01) | P5: Official Plan Row 7 (Task_Project_G1_IS2005.xlsx)
A6: 8 | B6: 2 | C6: Shared Foundation | D6: UNASSIGNED | E6: UNASSIGNED | F6: Unassigned / Milestone Header | G6: Cross-Module | H6: Unspecified | I6: Done | J6: N/A (Milestone/Section Grouping Container) | K6: Organizational milestone or phase umbrella header | L6: N/A | M6: UNASSIGNED | N6: NOT_ASSESSABLE | O6: Milestone structure verified in planning baseline | P6: Official Plan Row 8 (Task_Project_G1_IS2005.xlsx)
A7: 9 | B7: 2.1.1 | C7: Documents | D7: All | E7: ALL | F7: All Team Members | G7: Cross-Module / Shared Foundation | H7: Medium | I7: Done | J7: Branch origin/main; commits by team in docs, shared configs, reports | K7: Shared project documentation, architecture schemas, and requirement specifications | L7: Shared verification test suites (252 shared backend tests) | M7: MATCHED | N7: COMPLETED_VERIFIED | O7: Verified as collaborative shared foundation task | P7: Official Plan Row 9 (Task_Project_G1_IS2005.xlsx)
A8: 10 | B8: 2.1.2 | C8: Report 1: Project Introduction | D8: All | E8: ALL | F8: All Team Members | G8: Cross-Module / Shared Foundation | H8: Simple | I8: Done | J8: Branch origin/main; commits by team in docs, shared configs, reports | K8: Shared project documentation, architecture schemas, and requirement specifications | L8: Shared verification test suites (252 shared backend tests) | M8: MATCHED | N8: COMPLETED_VERIFIED | O8: Verified as collaborative shared foundation task | P8: Official Plan Row 10 (Task_Project_G1_IS2005.xlsx)
A9: 11 | B9: 2.2.1 | C9: Draw Main Business Flow BF-01 – Guest Onboarding & Wellness Profile Setup | D9: Đức Hoàng | E9: MEM-01 | F9: Lê Đức Hoàng | G9: M1 - Identity & Access | H9: Simple | I9: Done | J9: Branch DucHoangM1 (13 commits); merged in 602c6f8 | K9: AuthController, CustomerProfileController, GdprController, UserDetailsServiceImpl | L9: 77 backend tests in M1; mocked Google/Facebook SSO slices | M9: MATCHED | N9: COMPLETED_VERIFIED | O9: Implementation verified in code; external SSO/OTP live callbacks require staging (GAP-02, GAP-08) | P9: Official Plan Row 11 (Task_Project_G1_IS2005.xlsx)
A10: 12 | B10: 2.2.2 | C10: Draw Main Business Flow BF-02 – Retreat Booking, Deposit & Check-In | D10: Gia Đạt | E10: MEM-02 | F10: Nguyễn Gia Đạt | G10: M2 - Booking & Reservation | H10: Simple | I10: Done | J10: Branch dat-nguyen-gia (8 commits); commit 4bd4ecd (3417 lines); merged in 0f257ad | K10: RetreatPackageController, ReceptionistOperationController, BookingController, VNPayClient | L10: 34 backend tests in M2 (ReceptionistOperationServiceTest) | M10: MATCHED | N10: COMPLETED_VERIFIED | O10: Core workflow verified in code; live VNPay IPN webhook callbacks require staging (GAP-01) | P10: Official Plan Row 12 (Task_Project_G1_IS2005.xlsx)
A11: 13 | B11: 2.2.3 | C11: Draw Main Business Flow BF-03 – Spa/Therapy Scheduling & Session Fulfillment | D11: Tất Đạt | E11: MEM-03 | F11: Nguyễn Tất Đạt | G11: M3 - Spa & Shared Infrastructure | H11: Simple | I11: Done | J11: Branch NTDatZB (102 commits); merge commits 602c6f8, 0f257ad, 6ff5b9a, 39b086f, 9668586, 1f7ebc1 | K11: SpaTreatmentController, SpaBookingService, CustomerStayPort, SecurityConfig, Design Tokens | L11: 24 M3 tests + 252 shared infra tests (242 passed, 10 skipped live DB) | M11: MATCHED | N11: COMPLETED_VERIFIED | O11: Technical leadership, shared infrastructure, and spa operations verified | P11: Official Plan Row 13 (Task_Project_G1_IS2005.xlsx)
A12: 14 | B12: 2.2.4 | C12: Draw Main Business Flow BF-04 – Personalized Dining & F&B Service Fulfillment | D12: Phương Thảo | E12: MEM-04 | F12: Vũ Phương Thảo | G12: M4 - Food & Beverage | H12: Simple | I12: Done | J12: Branch thao-product (57 commits); merged in 6ff5b9a | K12: FnbMenuController, DailyMealOrderController, KdsKitchenController, InventoryGuard | L12: 42 backend tests in M4 (MealOrderServiceTest, InventoryServiceTest) | M12: MATCHED | N12: COMPLETED_VERIFIED | O12: Granular implementation verified; KDS queue and inventory deductions tested | P12: Official Plan Row 14 (Task_Project_G1_IS2005.xlsx)
... A182: 185 | B182: NOTE (Footnote) | C182: Thực tế 11/11 là buổi học cuối của môn trước khi lên hội đồng | D182: UNASSIGNED (Planning Footnote) | E182: N/A | F182: Planning Footnote (Administrative Note) | G182: Planning Milestone / Footnote | H182: N/A | I182: NO_STATUS | J182: N/A (Administrative schedule note at bottom of Official Plan sheet) | K182: Not a functional deliverable; records academic course schedule deadline | L182: N/A | M182: PLANNING_FOOTNOTE | N182: NOT_ASSESSABLE | O182: Planning footnote in Official Plan row 185; not a functional WBS task. Explains the 180 functional WBS tasks (rows 4-183) vs 181 populated Excel rows. | P182: Official Plan Row 185 (Task_Project_G1_IS2005.xlsx)

Sheet Contribution_Log
A1: Contribution_ID | B1: Original_Person_Name | C1: Canonical_Person_Name | D1: Module | E1: Contribution_Type | F1: Feature_Task | G1: Commit_Or_PR | H1: Files_Changed | I1: Evidence_Location | J1: Outcome_Summary | K1: Verification_Status | L1: Confidence | M1: Runtime_Limitations | N1: Reconciliation_Notes
A2: CONTRIB-01 | B2: Lê Đức Hoàng | C2: Lê Đức Hoàng | D2: M1 | E2: A | F2: Google SSO Integration | G2: ffdd40a | H2: SsoController.java; SsoService.java; SsoClientConfig.java | I2: Git commit ffdd40a; SsoAuthEndpointTests (14/14 pass) | J2: Implemented Google OAuth2 login and redirect handlers | K2: PARTIALLY_VERIFIED | L2: MEDIUM | M2: Mocked local slices pass; live third-party OAuth2 network handshakes require staging secrets (GAP-02 open) | N2: Mock flows tested; production credentials needed for live SSO
A3: CONTRIB-02 | B3: Lê Đức Hoàng | C3: Lê Đức Hoàng | D3: M1 | E3: A | F3: Facebook SSO & Ticket Linking | G3: 4f2db9b | H3: SsoLinkRequest.java; SsoTicketService.java; SsoCallbackPage.tsx | I3: Git commit 4f2db9b; SsoTicketServiceTest (6/6 pass) | J3: Implemented Facebook SSO exchange and account linking tickets | K3: PARTIALLY_VERIFIED | L3: MEDIUM | M3: Mocked local slices pass; live third-party OAuth2 network handshakes require staging secrets (GAP-02 open) | N3: Merged into integration branch in commit 602c6f8
A4: CONTRIB-03 | B4: Lê Đức Hoàng | C4: Lê Đức Hoàng | D4: M1 | E4: B | F4: Email OTP Registration Flow | G4: 1dcc3b1; ca0383c | H4: EmailOtp.java; DevEmailDeliveryAdapter.java; RegisterPage.tsx | I4: Git commits 1dcc3b1 ca0383c; DevEmailDeliveryAdapterTest pass | J4: Implemented OTP generation email dispatch and registration verification | K4: PARTIALLY_VERIFIED | L4: MEDIUM | M4: OTP generation and verification logic fully tested; live SMTP delivery requires production credentials (GAP-08 open) | N4: Dev adapter logs OTP to console; SMTP adapter ready for production
A5: CONTRIB-04 | B5: Lê Đức Hoàng | C5: Lê Đức Hoàng | D5: M1 | E5: B | F5: Customer & Health Profile Management | G5: ff49668; 700bdd0 | H5: CustomerProfileController.java; HealthProfileController.java | I5: Git commits ff49668 700bdd0; CustomerProfileControllerTests (8/8 pass) | J5: Implemented customer profile and medical intake management | K5: VERIFIED | L5: HIGH | M5: Local tests passing in H2 MSSQLServer mode | N5: Persists dietary allergies and emergency contact details
A6: CONTRIB-05 | B6: Lê Đức Hoàng | C6: Lê Đức Hoàng | D6: M1 | E6: B | F6: GDPR Health Data Deletion Request (Screen #9) | G6: bc9100a | H6: HealthDataDeletionRequestController.java; HealthDataDeletionPage.tsx | I6: Git commit bc9100a; HealthDataDeletionRequestServiceTest pass | J6: Implemented GDPR right-to-be-forgotten deletion request workflow | K6: VERIFIED | L6: HIGH | M6: Local tests passing in H2 MSSQLServer mode | N6: Provides audit trail for health record removal
A7: CONTRIB-06 | B7: Lê Đức Hoàng | C7: Lê Đức Hoàng | D7: M1 | E7: E | F7: M1 Identity & Access Test Suite | G7: 1d9750e | H7: AuthServiceTest.java; SsoAuthEndpointTests.java; AccountLockoutIntegrationTest.java | I7: Git commits; 77 passing M1 backend tests | J7: Authored comprehensive test suites for authentication and security | K7: VERIFIED | L7: HIGH | M7: Local tests passing in H2 MSSQLServer mode | N7: All 77 M1 tests pass cleanly in test suite
A8: CONTRIB-07 | B8: Lê Đức Hoàng | C8: Lê Đức Hoàng | D8: M1 | E8: J | F8: M1 Architecture Documentation & Handoff | G8: a3f82d9; 1d9750e | H8: M1_HANDOFF_CONTEXT.md; M1_Phase1_Audit.md; M1_Phase2_Plan.md | I8: Repository markdown files; commit metadata | J8: Detailed handoff context and migration preflight specifications | K8: VERIFIED | L8: HIGH | M8: Local tests passing in H2 MSSQLServer mode | N8: Clear documentation of M1 architecture and contract boundaries
A9: CONTRIB-08 | B9: Nguyễn Gia Đạt | C9: Nguyễn Gia Đạt | D9: M2 | E9: B | F9: Receptionist Operations Backend | G9: 4bd4ecd | H9: ReceptionistOperationController.java; ReceptionistOperationService.java | I9: Git commit 4bd4ecd; ReceptionistOperationServiceTest (5/5 pass) | J9: Implemented daily arrival check-in walk-in booking and room assignment | K9: VERIFIED | L9: HIGH | M9: Local tests passing in H2 MSSQLServer mode | N9: Integrated into baseline in commit 0f257ad
A10: CONTRIB-09 | B10: Nguyễn Gia Đạt | C10: Nguyễn Gia Đạt | D10: M2 | E10: B | F10: Retreat Booking Creation & Pricing | G10: 4bd4ecd | H10: RetreatBookingController.java; RetreatBookingService.java; BookingPolicyService.java | I10: Git commit 4bd4ecd; RetreatBookingServiceTest pass | J10: Implemented retreat reservation pricing deposit and inventory checks | K10: VERIFIED | L10: HIGH | M10: Local tests passing in H2 MSSQLServer mode | N10: Integrated into baseline in commit 0f257ad
A11: CONTRIB-10 | B11: Nguyễn Gia Đạt | C11: Nguyễn Gia Đạt | D11: M2 | E11: B | F11: VNPay Deposit Gateway Integration | G11: 4bd4ecd | H11: VNPayDepositService.java; VNPayCallbackController.java | I11: Git commit 4bd4ecd; VNPayDepositServiceTest pass | J11: Implemented VNPay HMAC-SHA512 deposit payment URL generation and callback | K11: PARTIALLY_VERIFIED | L11: MEDIUM | M11: Checksum hash algorithm verified; live VNPay IPN webhook callbacks require staging gateway (GAP-01 open) | N11: Integrated into baseline in commit 0f257ad; live gateway unverified
A12: CONTRIB-11 | B12: Nguyễn Gia Đạt | C12: Nguyễn Gia Đạt | D12: M2 | E12: B | F12: Customer Identity & Stay Adapter | G12: 4bd4ecd | H12: CustomerIdentityPort.java; JdbcCustomerIdentityAdapter.java | I12: Git commit 4bd4ecd; M2SchemaCompatibilityTest pass | J12: Implemented customer profile resolution across booking operations | K12: VERIFIED | L12: HIGH | M12: Local tests passing in H2 MSSQLServer mode | N12: Bridges M1 customer identity with M2 booking records
... A45: CONTRIB-44 | B45: Phan Thành Vinh | C45: Phạm Thành Vinh | D45: M6 | E45: J | F45: Business Flow Tracing & Requirements Analysis | G45: 6de3f95 | H45: 02_Requirement/Improve/Need_Improve/Manager.docx; admin.docx | I45: Git commit 6de3f95; requirement documents in repo | J45: Authored detailed business flow analysis and requirement improvement notes | K45: VERIFIED | L45: HIGH | M45: Local tests passing in H2 MSSQLServer mode | N45: Documented screen flows and operational role requirements

Sheet Module_Completeness
A1: Module | B1: Feature_ID | C1: Feature_Or_Function | D1: Scope_Taxonomy | E1: Backend_Evidence | F1: Frontend_Evidence | G1: Database_Dependency | H1: Test_Evidence | I1: Implementation_Status | J1: Runtime_Status | K1: Verification_Confidence | L1: Reconciliation_Scope_Notes
A2: M1 | B2: M1-F01 | C2: User Registration & Email OTP Verification | D2: Core Business Use Case & Technical Capability | E2: AuthController; AuthService; DevEmailDeliveryAdapter | F2: RegisterPage; EmailOtpVerificationPage | G2: dbo.User; dbo.EmailOtp | H2: AuthServiceTest; DevEmailDeliveryAdapterTest (pass) | I2: IMPLEMENTED_EVIDENCE_FOUND | J2: AUTOMATED_TESTS_ONLY | K2: HIGH | L2: Part of 49 granular technical inventory (represents 27 core SRS business use cases). Live SMTP / SendGrid credentials required for production delivery
A3: M1 | B3: M1-F02 | C3: User Login & JWT Token Issuance / Refresh | D3: Core Business Use Case & Technical Capability | E3: AuthController; AuthService; JwtTokenProvider | F3: LoginPage; AuthProvider | G3: dbo.User; dbo.UserRole; dbo.Role | H3: AuthLoginEndpointTests (5/5 pass); JwtTokenProviderTest | I3: IMPLEMENTED_EVIDENCE_FOUND | J3: AUTOMATED_TESTS_ONLY | K3: HIGH | L3: Part of 49 granular technical inventory (represents 27 core SRS business use cases). Verified with in-memory H2; production token secret should be kept in env
A4: M1 | B4: M1-F03 | C4: Google & Facebook SSO Integration | D4: Core Business Use Case & Technical Capability | E4: SsoController; SsoService; SsoOAuth2SuccessHandler | F4: SsoCallbackPage; LoginPage | G4: dbo.AuthIdentity; dbo.User | H4: SsoAuthEndpointTests (14/14 pass); SsoTicketServiceTest | I4: IMPLEMENTED_EVIDENCE_FOUND | J4: NOT_RUNTIME_VERIFIED | K4: HIGH | L4: Part of 49 granular technical inventory (represents 27 core SRS business use cases). Mock HTTP callbacks verified; live OAuth2 handshake with Google/Facebook requires staging
A5: M1 | B5: M1-F04 | C5: Account Lockout & Auto-Unlock Background Job | D5: Core Business Use Case & Technical Capability | E5: AuthService; AccountUnlockJob | F5: LoginPage (error feedback) | G5: dbo.User (failed_attempts; lockout_until) | H5: AccountLockoutIntegrationTest (8/8 pass); AccountUnlockJobTest | I5: IMPLEMENTED_EVIDENCE_FOUND | J5: AUTOMATED_TESTS_ONLY | K5: HIGH | L5: Part of 49 granular technical inventory (represents 27 core SRS business use cases). Verified in Spring test slice; scheduler active in application lifecycle
A6: M1 | B6: M1-F05 | C6: Customer Profile Management & ToS Consent | D6: Core Business Use Case & Technical Capability | E6: CustomerProfileController; ConsentController; CustomerProfileService | F6: AccountSettingsPage; CustomerContext | G6: dbo.CustomerProfile; dbo.ConsentRecord | H6: CustomerProfileControllerTests (8/8 pass); ConsentServiceTest | I6: IMPLEMENTED_EVIDENCE_FOUND | J6: AUTOMATED_TESTS_ONLY | K6: HIGH | L6: Part of 49 granular technical inventory (represents 27 core SRS business use cases). Profile updates and consent tracking functional
A7: M1 | B7: M1-F06 | C7: Customer Health Profile & Dietary Intake | D7: Core Business Use Case & Technical Capability | E7: HealthProfileController; HealthProfileService | F7: HealthProfilePage; CustomerContext | G7: dbo.HealthProfile; dbo.DietaryRequirement; dbo.FoodAllergy | H7: HealthProfileServiceTest pass | I7: IMPLEMENTED_EVIDENCE_FOUND | J7: AUTOMATED_TESTS_ONLY | K7: HIGH | L7: Part of 49 granular technical inventory (represents 27 core SRS business use cases). Medical notes and emergency contacts mapped
A8: M1 | B8: M1-F07 | C8: GDPR Health Data Deletion Request (Screen #9) | D8: Core Business Use Case & Technical Capability | E8: HealthDataDeletionRequestController; HealthDataDeletionRequestService | F8: HealthDataDeletionPage | G8: dbo.HealthDataDeletionRequest; dbo.CustomerProfile | H8: HealthDataDeletionRequestServiceTest (pass) | I8: IMPLEMENTED_EVIDENCE_FOUND | J8: AUTOMATED_TESTS_ONLY | K8: HIGH | L8: Part of 49 granular technical inventory (represents 27 core SRS business use cases). GDPR compliance flow with review audit trail
A9: M1 | B9: M1-F08 | C9: Local Dev Authentication Bypass | D9: Core Business Use Case & Technical Capability | E9: DevAuthController | F9: Dev login quick buttons | G9: None | H9: /api/v1/auth/dev/** permitted in SecurityConfig | I9: IMPLEMENTED_EVIDENCE_FOUND | J9: AUTOMATED_TESTS_ONLY | K9: HIGH | L9: Part of 49 granular technical inventory (represents 27 core SRS business use cases). CRITICAL SECURITY NOTE: Must be disabled or profile-locked in production
A10: M2 | B10: M2-F01 | C10: Retreat Package Browsing & Filtering | D10: Core Business Use Case & Technical Capability | E10: RetreatPackageController; RetreatPackageService | F10: RetreatListPage; RetreatDetailPage | G10: dbo.RetreatPackage; dbo.PackageVillaCategoryMapping | H10: M2SchemaCompatibilityTest (6/6 pass) | I10: IMPLEMENTED_EVIDENCE_FOUND | J10: AUTOMATED_TESTS_ONLY | K10: HIGH | L10: Part of 49 granular technical inventory (represents 27 core SRS business use cases). Public browsing verified against mock/in-memory data
A11: M2 | B11: M2-F02 | C11: Public Retreat Booking Creation & Pricing | D11: Core Business Use Case & Technical Capability | E11: RetreatBookingController; RetreatBookingService; BookingPolicyService | F11: RetreatBookingPage; BookingSummaryPage | G11: dbo.RetreatBooking; dbo.VillaCategory | H11: RetreatBookingServiceTest; BookingPolicyService pass | I11: IMPLEMENTED_EVIDENCE_FOUND | J11: AUTOMATED_TESTS_ONLY | K11: HIGH | L11: Part of 49 granular technical inventory (represents 27 core SRS business use cases). Deposit calculation verified; inventory check enforced
A12: M2 | B12: M2-F03 | C12: VNPay Deposit Payment Gateway Integration | D12: Core Business Use Case & Technical Capability | E12: VNPayDepositService; VNPayCallbackController | F12: DepositPaymentResultPage; retreatBookingApi | G12: dbo.PaymentTransaction; dbo.RetreatBooking | H12: VNPayDepositServiceTest; checksum unit tests pass | I12: IMPLEMENTED_EVIDENCE_FOUND | J12: NOT_RUNTIME_VERIFIED | K12: HIGH | L12: Part of 49 granular technical inventory (represents 27 core SRS business use cases). HMAC-SHA512 checksum algorithms verified; live VNPay gateway redirect pending staging
... A50: INFRA | B50: INFRA-06 | C50: Database Schema & In-Memory Test Harness | D50: Granular Technical Component | E50: schema.sql; application.yml | F50: None | G50: 42 tables in schema.sql | H50: 536 backend tests pass; H2 MSSQLServer mode verified | I50: IMPLEMENTED_EVIDENCE_FOUND | J50: AUTOMATED_TESTS_ONLY | K50: HIGH | L50: Part of 49 granular technical inventory (represents 27 core SRS business use cases). In-memory H2 compatibility verified; live SQL Server test execution deferred

Sheet Test_Evidence
A1: Test_Area | B1: Test_Suite_Or_Target | C1: Total_Tests | D1: Passed | E1: Failed | F1: Skipped | G1: Environment | H1: Execution_Time | I1: Evidence_Hierarchy_Type | J1: Audit_Verification_Status | K1: What_It_Proves | L1: What_It_Does_Not_Prove | M1: Reconciliation_Notes
A2: Backend Aggregate (Reported) | B2: Full Maven Backend Test Suite (Aggregate Log) | C2: 536 | D2: 526 | E2: 0 | F2: 10 | G2: Java 17 / Maven 3.9 / H2 in-memory (MODE=MSSQLServer) | H2: 2m 16s | I2: PRIMARY_PHASE_118_BUILD_LOG | J2: REPORTED_FROM_PHASE_118_LOGS | K2: Reported Maven test execution completed with BUILD SUCCESS in Phase 5.8.3.118 | L2: Does not represent independent re-execution during read-only audit turn; live SQL Server tests skipped by design | M2: Preserved from PHASE_5.8.3.117-5.8.3.118_FULL_TEAM_MERGE_HISTORY.txt lines 75-76 and line 366.
A3: Backend M1 | B3: M1 Identity & Access Test Suites | C3: 77 | D3: 77 | E3: 0 | F3: 0 | G3: H2 in-memory / MockMvc / Spring Security slices | H3: 18.4s | I3: DERIVED_MODULE_BREAKDOWN | J3: REPORTED_IN_MODULE_SUMMARY | K3: Account lockout auto-unlock, JWT token validation, password hashing, and mocked SSO ticket flows | L3: Live Google/Facebook OAuth2 network redirects and production SMTP delivery (GAP-02, GAP-08) | M3: Merge history lines 624-629 document sample key suites (41 tests); full module total reported at 77 tests.
A4: Backend M2 | B4: M2 Retreat Booking Test Suites | C4: 34 | D4: 34 | E4: 0 | F4: 0 | G4: H2 in-memory / Spring Boot test context | H4: 14.2s | I4: DERIVED_MODULE_BREAKDOWN | J4: REPORTED_IN_MODULE_SUMMARY | K4: Retreat booking creation, deposit calculation, villa assignment, receptionist operations, and VNPay checksum hashing | L4: Live VNPay gateway IPN callback network handling and concurrent room booking contention (GAP-01, GAP-07) | M4: Merge history lines 630-634 document sample key suites (26 tests); full module total reported at 34 tests.
A5: Backend M3 | B5: M3 Spa & Wellness Test Suites | C5: 24 | D5: 24 | E5: 0 | F5: 0 | G5: H2 in-memory / Mockito slices | H5: 11.5s | I5: DERIVED_MODULE_BREAKDOWN | J5: REPORTED_IN_MODULE_SUMMARY | K5: Treatment catalog, therapist schedule validation, conflict detection, and session lifecycle transitions | L5: Physical room lock acquisition timing under live multi-threaded database load | M5: Merge history line 636 documents sample suite SpaServiceTests (12 tests); full module total reported at 24 tests.
A6: Backend M4 | B6: M4 Food & Beverage Test Suites | C6: 42 | D6: 42 | E6: 0 | F6: 0 | G6: H2 in-memory / Spring Boot test context | H6: 16.8s | I6: DERIVED_MODULE_BREAKDOWN | J6: REPORTED_IN_MODULE_SUMMARY | K6: Menu allergen filtering, daily meal plan placement, KDS lifecycle transitions, and recipe inventory deduction | L6: Kitchen printing hardware integration and multi-day meal schedule bulk ordering | M6: Merge history lines 637-642 document sample key suites (30 tests); full module total reported at 42 tests.
A7: Backend M5 | B7: M5 Billing & Checkout Test Suites | C7: 48 | D7: 48 | E7: 0 | F7: 0 | G7: H2 in-memory / Spring Boot test context | H7: 21.3s | I7: PRIMARY_SUITE_LOG | J7: REPORTED_IN_MODULE_SUMMARY | K7: Real-time folio aggregation, multi-item posting, VAT calculation, PDF generation, and customer reviews | L7: Payment terminal hardware integrations and high-volume invoice streaming under production load | M7: Merge history line 644 documents M5BillingAndCheckoutTests (48/48 passed).
A8: Backend M6 | B8: M6 Admin & Governance Test Suites | C8: 49 | D8: 49 | E8: 0 | F8: 0 | G8: H2 in-memory / Spring Boot test context | H8: 17.1s | I8: DERIVED_MODULE_BREAKDOWN | J8: REPORTED_IN_MODULE_SUMMARY | K8: Granular RBAC permission checks, staff account management, temporary manager delegation, and audit log | L8: Cluster-wide distributed cache invalidation upon parameter changes | M8: Merge history lines 645-650 document sample key suites (39 tests); full module total reported at 49 tests.
A9: Backend Shared | B9: Security Context & Infrastructure Suites | C9: 252 | D9: 242 | E9: 0 | F9: 10 | G9: H2 in-memory / Spring Security / WebMvc slices | H9: 37.1s | I9: DERIVED_INFRA_BREAKDOWN | J9: REPORTED_IN_MODULE_SUMMARY | K9: Dual-chain security filter matching, global exception mapping, and UTF-8 encoding sanitization | L9: Live SQL Server 2022 connection pooling and distributed transaction coordinators | M9: Reported at 242 passed + 10 skipped = 252 total. M1-M6 (274 passed) + Shared (242 passed) = 516 passed.
A10: Backend Live DB | B10: Opt-In SQL Server Smoke Tests (Guard) | C10: 10 | D10: 0 | E10: 0 | F10: 10 | G10: SQL Server (Target HSWRMS_TEST ID 45) - Opt-in disabled | H10: 0.1s | I10: PRIMARY_OPT_IN_GUARD | J10: SKIPPED_BY_DESIGN | K10: Safe opt-in guard prevents accidental mutations when env variables are absent | L10: Does not prove SQL Server 2022 live runtime compatibility since tests were skipped | M10: Merge history lines 729-730 explicitly confirm smoke tests remained skipped by default to protect DB.
A11: Backend Reconciliation Variance | B11: Unallocated Tests between Detailed Breakdown (516 Passed) and Reported Aggregate (526 Passed) | C11: 10 | D11: UNRESOLVED | E11: 0 | F11: 0 | G11: H2 in-memory / Detailed Category Allocation Gap | H11: N/A | I11: AUDIT_RECONCILIATION_FINDING | J11: UNRESOLVED_BREAKDOWN_VARIANCE | K11: Identifies exact mathematical 10-test gap between granular module rows (516 passed) and reported build aggregate (526 passed) | L11: Does not fabricate 10 passed tests to force a balance; records reconciliation variance pending Surefire XML log inspection | M11: Preserves Phase 118 aggregate (526 passed, 10 skipped, 536 total). Source text provides sample suites only; per-module breakdown cannot be resolved from supplied text alone.
A12: Frontend Build | B12: Vite Production Build & TypeScript Typecheck | C12: 2728 | D12: 2728 | E12: 0 | F12: 0 | G12: Node.js / Vite v8.3.4 / TypeScript ~6.0.2 | H12: 997ms | I12: PRIMARY_BUILD_LOG | J12: REPORTED_FROM_BUILD_LOGS | K12: Zero TypeScript compilation errors; all 2,728 modules transformed cleanly without syntax errors | L12: Runtime browser DOM interaction across different screen sizes and browsers | M12: Documented in merge history lines 652-662.
A13: Frontend Lint | B13: Oxlint Static Analysis Audit | C13: 216 | D13: 216 | E13: 0 | F13: 0 | G13: Oxlint v1.81.0 (96 rules across 216 files) | H13: 85ms | I13: PRIMARY_LINT_LOG | J13: REPORTED_FROM_LINT_LOGS | K13: Zero linting errors across 216 files; 10 informational non-blocking unused-variable warnings in fallback catches | L13: Runtime state reactivity or user interaction latency | M13: Documented in merge history lines 663-667.
A14: Frontend Slices | B14: Frontend Contract & Safety Test Suites | C14: 10 | D14: 10 | E14: 0 | F14: 0 | G14: Vitest / Node.js test runner | H14: 2.4s | I14: DERIVED_SLICE_LOG | J14: REPORTED_FROM_SLICE_LOGS | K14: Client-side payment safety checks, booking resolvers, KDS queue safety, and admin API contracts | L14: End-to-end browser DOM interaction and live network latency | M14: Documented in frontend unit test reports.

Sheet Gap_Register
A1: Gap_ID | B1: Module | C1: Gap_Defect_Risk | D1: Evidence | E1: Gap_Category | F1: Impact | G1: Priority | H1: Proposed_Task | I1: Suggested_Owner_Raw | J1: Canonical_Owner | K1: Acceptance_Criteria | L1: Dependencies | M1: Audit_Status | N1: Verification_Note
A2: GAP-01 | B2: M2/M5 | C2: Third-Party Payment Gateway Runtime Verification | D2: VNPayDepositServiceTest and CheckoutService test checksums via mocks; live VNPay IPN and redirect untried | E2: Runtime verification gap | F2: HIGH | G2: P1 | H2: Configure VNPay sandbox credentials and verify live roundtrip deposit and checkout settlement | I2: Nguyễn Gia Đạt & Trần Xuân Hòa (Proposed) | J2: Nguyễn Gia Đạt & Tăng Xuân Hòa (Proposed) | K2: Live VNPay callback updates payment status in database and marks folio paid without errors | L2: VNPay sandbox credentials and public network tunnel | M2: OPEN | N2: Confirmed OPEN; no live runtime verification was authorized during audit
A3: GAP-02 | B3: M1 | C3: Third-Party OAuth2 SSO Runtime Verification | D3: SsoAuthEndpointTests verify OAuth2 handlers via MockMvc; live Google/Facebook handshakes untried | E3: Runtime verification gap | F3: HIGH | G3: P1 | H3: Configure Google and Facebook OAuth2 client secrets and verify live redirect login on staging | I3: Lê Đức Hoàng (Proposed) | J3: Lê Đức Hoàng (Proposed) | K3: Successful browser redirect login resulting in valid JWT issued to user | L3: Google/Facebook developer console app credentials | M3: OPEN | N3: Confirmed OPEN; no live runtime verification was authorized during audit
A4: GAP-03 | B4: Database | C4: Unexecuted Business Catalog Seed in HSWRMS_TEST | D4: Phase 5.8.3.112 seed execution failed on syntax error; fixed in 113 but script never re-executed; tables hold 0 rows | E4: Database alignment | F4: HIGH | G4: P1 | H4: Execute remediated hswrms_test_business_catalog_seed.sql against HSWRMS_TEST under operator authorization | I4: Nguyễn Tất Đạt (Proposed) | J4: Nguyễn Tất Đạt (Proposed) | K4: All 10 business catalog tables populated with baseline reference data without syntax errors | L4: Operator authorization to connect to HSWRMS_TEST | M4: OPEN | N4: Confirmed OPEN; no live runtime verification was authorized during audit
A5: GAP-04 | B5: Database | C5: Sequential Migration Ordering for 4 Deferred Migration Scripts | D5: 4 migration scripts (V003 V004 V005 draft_m6) remain untracked in migrations directory | E5: Database alignment | F5: MEDIUM | G5: P1 | H5: Formulate Flyway migration baseline roadmap and assign strict sequential version numbering | I5: Nguyễn Tất Đạt (Proposed) | J5: Nguyễn Tất Đạt (Proposed) | K5: Flyway clean migration test completes against fresh database without FK or duplicate errors | L5: Resolution of canonical schema baseline | M5: OPEN | N5: Confirmed OPEN; no live runtime verification was authorized during audit
A6: GAP-05 | B6: Security | C6: Local Development Authentication Bypass Endpoint in SecurityConfig | D6: SecurityConfig.java has requestMatchers(/api/v1/auth/dev/**).permitAll(); DevAuthController issues instant JWT | E6: Security review | F6: CRITICAL | G6: P0 | H6: Restrict dev authentication endpoints to dev Spring profile only (@Profile(dev)) | I6: Lê Đức Hoàng & Nguyễn Tất Đạt (Proposed) | J6: Lê Đức Hoàng & Nguyễn Tất Đạt (Proposed) | K6: Endpoint returns 404/403 in default/production profile; dev bypass impossible in prod | L6: Profile configuration in application.yml | M6: OPEN | N6: Confirmed OPEN; no live runtime verification was authorized during audit
A7: GAP-06 | B7: Cross-Module | C7: End-to-End Operational Lifecycle Traversal Across M1-M6 | D7: All module tests pass in isolation; complete end-to-end user journey untried in running deployment | E7: Runtime verification gap | F7: HIGH | G7: P1 | H7: Deploy backend and frontend to staging server and perform full end-to-end user walkthrough | I7: Entire Team (Facilitated by Nguyễn Tất Đạt) (Proposed) | J7: Entire Team (Facilitated by Nguyễn Tất Đạt) (Proposed) | K7: Guest books retreat -> Check-in -> Order meal in KDS -> Attend spa -> Single checkout folio printed | L7: Staging environment deployment | M7: OPEN | N7: Confirmed OPEN; no live runtime verification was authorized during audit
A8: GAP-07 | B8: M2/M4 | C8: High-Concurrency Contention Under Live Database Connection Pool | D8: H2 tests do not simulate concurrent row locks; SQL Server UPDLOCK hints need multi-threaded verification | E8: Performance/concurrency | F8: MEDIUM | G8: P2 | H8: Execute concurrency load test for simultaneous room booking and kitchen inventory deduction | I8: Nguyễn Gia Đạt & Vũ Phương Thảo (Proposed) | J8: Nguyễn Gia Đạt & Vũ Phương Thảo (Proposed) | K8: Zero double-bookings and zero negative stock balances under 50 concurrent requests | L8: Live database connection pool (HikariCP) | M8: OPEN | N8: Confirmed OPEN; no live runtime verification was authorized during audit
A9: GAP-08 | B9: M1 | C9: Live Production Email Delivery Configuration | D9: DevEmailDeliveryAdapter logs OTP codes to console; live SMTP adapter requires active credentials | E9: Runtime verification gap | F9: LOW | G9: P2 | H9: Configure SMTP host username password in production environment variables | I9: Lê Đức Hoàng (Proposed) | J9: Lê Đức Hoàng (Proposed) | K9: Real email OTP delivered to customer inbox within 30 seconds of registration | L9: Valid SMTP server or SendGrid API key | M9: OPEN | N9: Confirmed OPEN; no live runtime verification was authorized during audit

Sheet Scoring_Rubric
A1: Mã tiêu chí | B1: Tên tiêu chí đánh giá năng lực | C1: Trọng số | D1: Nhóm tiêu chí chuẩn | E1: Lê Đức Hoàng (M1) | F1: Nguyễn Gia Đạt (M2) | G1: Nguyễn Tất Đạt (M3+Lead) | H1: Vũ Phương Thảo (M4) | I1: Tăng Xuân Hòa (M5) | J1: Phạm Thành Vinh (M6) | K1: Bằng chứng đối soát chính | L1: Phương pháp xác minh
A2: TC-01 | B2: Mức độ hoàn thành nhiệm vụ (WBS) | C2: 0.1 | D2: Chuyên cần & WBS (20%) | E2: 9 | F2: 8.8 | G2: 9.8 | H2: 9.5 | I2: 9 | J2: 9 | K2: Bảng phân công WBS 180 tác vụ; lịch sử Git commit | L2: Đối chiếu WBS và code thực tế
A3: TC-02 | B3: Phạm vi chức năng & Độ phức tạp | C3: 0.15 | D3: Chất lượng Code (35%) | E3: 9.2 | F3: 9 | G3: 9.8 | H3: 9.2 | I3: 9.5 | J3: 9 | K3: Kiến trúc Controller, Service, DTO, Entity | L3: Đánh giá độ sâu logic nghiệp vụ
A4: TC-03 | B4: Chất lượng thiết kế & Clean Code | C4: 0.15 | D4: Chất lượng Code (35%) | E4: 9 | F4: 9 | G4: 9.8 | H4: 9.2 | I4: 9 | J4: 9 | K4: Mã nguồn backend và frontend; kết quả Oxlint | L4: Kiểm tra cấu trúc phân tầng
A5: TC-04 | B5: Xử lý nghiệp vụ & Edge Cases | C5: 0.1 | D5: Kiểm thử & Ổn định (25%) | E5: 9.2 | F5: 8.8 | G5: 9.8 | H5: 9.5 | I5: 9.2 | J5: 8.8 | K5: Service layer validation; Exception handlers | L5: Soát xét các kịch bản ngoại lệ
A6: TC-05 | B6: Kiểm thử tự động & Bằng chứng | C6: 0.15 | D6: Kiểm thử & Ổn định (25%) | E6: 9.5 | F6: 8.8 | G6: 9.8 | H6: 9 | I6: 9.5 | J6: 9 | K6: 536 tests backend; test slice frontend | L6: Kiểm tra báo cáo Maven Surefire
A7: TC-06 | B7: Sửa lỗi & Độ ổn định | C7: 0.05 | D7: Tích hợp & Phối hợp (20%) | E7: 9 | F7: 9 | G7: 9.8 | H7: 9.5 | I7: 8.8 | J7: 8.8 | K7: Commit fix bug: 52a6bd9, 299a37d, 1f7ebc1 | L7: Phân tích nguyên nhân và cách sửa
A8: TC-07 | B8: Tích hợp liên module & API Contracts | C8: 0.1 | D8: Tích hợp & Phối hợp (20%) | E8: 9 | F8: 8.8 | G8: 10 | H8: 9.2 | I8: 8.8 | J8: 8.8 | K8: Điểm chạm: M1-M2, M2-M5, M3-M5, M4-M5 | L8: Kiểm tra REST API contracts
A9: TC-08 | B9: Tài liệu kỹ thuật & Bàn giao | C9: 0.05 | D9: Chuyên cần & WBS (20%) | E9: 9.8 | F9: 8.5 | G9: 9.8 | H9: 9 | I9: 8.5 | J9: 9.2 | K9: M1_HANDOFF, SRS, README, Báo cáo Phase | L9: Đọc các file tài liệu markdown/docx
A10: TC-09 | B10: Chủ động phát hiện & Kiểm soát rủi ro | C10: 0.05 | D10: Chất lượng Code (35%) | E10: 8.8 | F10: 8.8 | G10: 10 | H10: 9.2 | I10: 8.5 | J10: 8.8 | K10: Báo cáo audit, quyết định selective merge | L10: Đánh giá các quyết định kỹ thuật
A11: TC-10 | B11: Phối hợp nhóm & Hỗ trợ tích hợp | C11: 0.05 | D11: Tích hợp & Phối hợp (20%) | E11: 9 | F11: 8.8 | G11: 10 | H11: 9.2 | I11: 8.8 | J11: 8.8 | K11: Lịch sử merge branch; giải quyết conflict | L11: Xem xét thái độ và kết quả hợp nhất
A12: TC-11 | B12: Mức độ xác minh kết quả cuối cùng | C12: 0.05 | D12: Chuyên cần & WBS (20%) | E12: 9.2 | F12: 8.8 | G12: 9.8 | H12: 9.2 | I12: 9.2 | J12: 9 | K12: Build success; 526 passed tests; 0 errors | L12: Đối chiếu kết quả kiểm thử thực tế
A13: TỔNG CỘNG | B13: Kiểm tra tổng trọng số & Điểm tính trực tiếp | C13: =SUM(C2:C12) | E13: =SUMPRODUCT($C$2:$C$12, E2:E12) | F13: =SUMPRODUCT($C$2:$C$12, F2:F12) | G13: =SUMPRODUCT($C$2:$C$12, G2:G12) | H13: =SUMPRODUCT($C$2:$C$12, H2:H12) | I13: =SUMPRODUCT($C$2:$C$12, I2:I12) | J13: =SUMPRODUCT($C$2:$C$12, J2:J12)

Sheet Member_Scorecard
A1: Mã thành viên | B1: Họ và tên chuẩn | C1: Bí danh / Alias Git | D1: MSSV | E1: Vai trò dự án | F1: Module chính | G1: Số commit Git | H1: Số bài test | I1: Chuyên cần & WBS (20%) | J1: Chất lượng Code (35%) | K1: Kiểm thử & Ổn định (25%) | L1: Tích hợp & Phối hợp (20%) | M1: Điểm tổng kết (Trực tiếp 11 tiêu chí) | N1: Xếp loại | O1: Độ tin cậy | P1: Đánh giá năng lực & Đóng góp nổi bật
A2: MEM-01 | B2: Lê Đức Hoàng | C2: Le Duc Hoang | D2: HE204568 | E2: Module 1 Lead / Developer | F2: M1 - Identity & Access | G2: 13 | H2: 77 | I2: =(Scoring_Rubric!E2*0.1 + Scoring_Rubric!E9*0.05 + Scoring_Rubric!E12*0.05)/0.2 | J2: =(Scoring_Rubric!E3*0.15 + Scoring_Rubric!E4*0.15 + Scoring_Rubric!E10*0.05)/0.35 | K2: =(Scoring_Rubric!E5*0.10 + Scoring_Rubric!E6*0.15)/0.25 | L2: =(Scoring_Rubric!E7*0.05 + Scoring_Rubric!E8*0.10 + Scoring_Rubric!E11*0.05)/0.2 | M2: =SUMPRODUCT(Scoring_Rubric!$C$2:$C$12, Scoring_Rubric!E2:Scoring_Rubric!E12) | N2: =IF(M2>=9.0,"Xuất sắc",IF(M2>=8.0,"Giỏi","Khá")) | O2: HIGH | P2: Hoàn thành xuất sắc phân hệ M1 bảo mật cao; tích hợp Google/Facebook SSO, email OTP, Screen #9 GDPR xóa dữ liệu; bộ test 77 bài pass 100%; tài liệu bàn giao M1_HANDOFF rất chi tiết.
A3: MEM-02 | B3: Nguyễn Gia Đạt | C3: Datnghe181035 | D3: HE181035 | E3: Module 2 Lead / Developer | F3: M2 - Booking & Reservation | G3: 8 | H3: 34 | I3: =(Scoring_Rubric!F2*0.1 + Scoring_Rubric!F9*0.05 + Scoring_Rubric!F12*0.05)/0.2 | J3: =(Scoring_Rubric!F3*0.15 + Scoring_Rubric!F4*0.15 + Scoring_Rubric!F10*0.05)/0.35 | K3: =(Scoring_Rubric!F5*0.10 + Scoring_Rubric!F6*0.15)/0.25 | L3: =(Scoring_Rubric!F7*0.05 + Scoring_Rubric!F8*0.10 + Scoring_Rubric!F11*0.05)/0.2 | M3: =SUMPRODUCT(Scoring_Rubric!$C$2:$C$12, Scoring_Rubric!F2:Scoring_Rubric!F12) | N3: =IF(M3>=9.0,"Xuất sắc",IF(M3>=8.0,"Giỏi","Khá")) | O3: HIGH | P3: Đóng góp khối lượng mã nguồn đồ sộ trong commit 4bd4ecd (3,417 dòng, 33 files); xây dựng toàn bộ nghiệp vụ lễ tân, tính giá cọc, tích hợp cổng VNPay và adapter danh tính khách; chủ động sửa lỗi lưu thông tin khách.
A4: MEM-03 | B4: Nguyễn Tất Đạt | C4: DZB1509 / datnthe181883 | D4: HE181883 | E4: Project Technical Lead / Integrator | F4: M3 - Spa & Shared Infrastructure | G4: 102 | H4: 24 | I4: =(Scoring_Rubric!G2*0.1 + Scoring_Rubric!G9*0.05 + Scoring_Rubric!G12*0.05)/0.2 | J4: =(Scoring_Rubric!G3*0.15 + Scoring_Rubric!G4*0.15 + Scoring_Rubric!G10*0.05)/0.35 | K4: =(Scoring_Rubric!G5*0.10 + Scoring_Rubric!G6*0.15)/0.25 | L4: =(Scoring_Rubric!G7*0.05 + Scoring_Rubric!G8*0.10 + Scoring_Rubric!G11*0.05)/0.2 | M4: =SUMPRODUCT(Scoring_Rubric!$C$2:$C$12, Scoring_Rubric!G2:Scoring_Rubric!G12) | N4: =IF(M4>=9.0,"Xuất sắc",IF(M4>=8.0,"Giỏi","Khá")) | O4: HIGH | P4: Đóng vai trò trụ cột kỹ thuật của toàn bộ dự án: phát triển phân hệ M3 Spa; thiết lập kiến trúc Spring Security kép, design tokens và layout chung; độc lập xử lý thành công 44 merge conflicts từ nhánh XH, chẩn đoán và khắc phục 2 lỗi test hồi quy phức tạp, duy trì 0 đột biến CSDL.
A5: MEM-04 | B5: Vũ Phương Thảo | C5: Thao Vu | D5: HE204054 | E5: Module 4 Lead / Developer | F5: M4 - Food & Beverage | G5: 57 | H5: 42 | I5: =(Scoring_Rubric!H2*0.1 + Scoring_Rubric!H9*0.05 + Scoring_Rubric!H12*0.05)/0.2 | J5: =(Scoring_Rubric!H3*0.15 + Scoring_Rubric!H4*0.15 + Scoring_Rubric!H10*0.05)/0.35 | K5: =(Scoring_Rubric!H5*0.10 + Scoring_Rubric!H6*0.15)/0.25 | L5: =(Scoring_Rubric!H7*0.05 + Scoring_Rubric!H8*0.10 + Scoring_Rubric!H11*0.05)/0.2 | M5: =SUMPRODUCT(Scoring_Rubric!$C$2:$C$12, Scoring_Rubric!H2:Scoring_Rubric!H12) | N5: =IF(M5>=9.0,"Xuất sắc",IF(M5>=8.0,"Giỏi","Khá")) | O5: HIGH | P5: Tinh thần làm việc bền bỉ và chuyên cần mẫu mực với 57 commits phân bổ đều đặn; hoàn thiện xuất sắc nghiệp vụ F&B trị liệu, bộ lọc dị ứng, quy trình điều phối bếp KDS thời gian thực, quản lý trừ kho nguyên liệu và bộ xử lý lỗi font UTF-8.
A6: MEM-05 | B6: Tăng Xuân Hòa | C6: Trần Xuân Hòa / hoatxhe180798 | D6: HE180798 | E6: Module 5 Lead / Developer | F6: M5 - Billing & Checkout | G6: 8 | H6: 48 | I6: =(Scoring_Rubric!I2*0.1 + Scoring_Rubric!I9*0.05 + Scoring_Rubric!I12*0.05)/0.2 | J6: =(Scoring_Rubric!I3*0.15 + Scoring_Rubric!I4*0.15 + Scoring_Rubric!I10*0.05)/0.35 | K6: =(Scoring_Rubric!I5*0.10 + Scoring_Rubric!I6*0.15)/0.25 | L6: =(Scoring_Rubric!I7*0.05 + Scoring_Rubric!I8*0.10 + Scoring_Rubric!I11*0.05)/0.2 | M6: =SUMPRODUCT(Scoring_Rubric!$C$2:$C$12, Scoring_Rubric!I2:Scoring_Rubric!I12) | N6: =IF(M6>=9.0,"Xuất sắc",IF(M6>=8.0,"Giỏi","Khá")) | O6: HIGH | P6: Đóng góp khối lượng nghiệp vụ tài chính khổng lồ trong commit ebaddc7 (7,608 dòng, 68 files); xây dựng logic tổng hợp Folio, thanh toán đa kênh, xuất hóa đơn VAT dạng PDF và báo cáo quản lý; bộ test M5 cực kỳ đồ sộ với 48 test pass 100%.
A7: MEM-06 | B7: Phạm Thành Vinh | C7: Phan Thành Vinh / pthanhvinh26112004 | D7: HE186593 | E7: Module 6 Lead / Developer | F7: M6 - Admin & Governance | G7: 22 | H7: 49 | I7: =(Scoring_Rubric!J2*0.1 + Scoring_Rubric!J9*0.05 + Scoring_Rubric!J12*0.05)/0.2 | J7: =(Scoring_Rubric!J3*0.15 + Scoring_Rubric!J4*0.15 + Scoring_Rubric!J10*0.05)/0.35 | K7: =(Scoring_Rubric!J5*0.10 + Scoring_Rubric!J6*0.15)/0.25 | L7: =(Scoring_Rubric!J7*0.05 + Scoring_Rubric!J8*0.10 + Scoring_Rubric!J11*0.05)/0.2 | M7: =SUMPRODUCT(Scoring_Rubric!$C$2:$C$12, Scoring_Rubric!J2:Scoring_Rubric!J12) | N7: =IF(M7>=9.0,"Xuất sắc",IF(M7>=8.0,"Giỏi","Khá")) | O7: HIGH | P7: Đóng góp rất lớn vào giao diện quản lý thực tế với 2 trang quản lý villa (2,765 dòng) và spa (1,843 dòng), 11 modal nghiệp vụ cấu hình phòng/giá; xây dựng tính năng phân quyền chi tiết RBAC, ủy quyền tạm thời, audit log và trích xuất báo cáo công an lưu trú.
A8: TRUNG BÌNH NHÓM | B8: Trung bình 6 sinh viên | G8: =AVERAGE(G2:G7) | H8: =AVERAGE(H2:H7) | I8: =AVERAGE(I2:I7) | J8: =AVERAGE(J2:J7) | K8: =AVERAGE(K2:K7) | L8: =AVERAGE(L2:L7) | M8: =AVERAGE(M2:M7)
A10: GIẢNG VIÊN HƯỚNG DẪN (TÁCH RIÊNG KHÔNG CHẤM ĐIỂM SINH VIÊN)
A11: MEM-07 | B11: Nguyễn Cường Mạnh | C11: Nguyen Cuong Manh | D11: GIẢNG VIÊN | E11: Course Instructor / Project Supervisor | F11: Course Governance & Supervision | G11: 1 | H11: 0 | I11: N/A | J11: N/A | K11: N/A | L11: N/A | M11: N/A | N11: Giảng viên | O11: HIGH | P11: Giảng viên hướng dẫn môn học, chủ sở hữu namespace GitLab manhnc2. Tách biệt hoàn toàn khỏi thang điểm đóng góp và xếp loại học tập của 6 sinh viên.

Sheet Conflict_Register
A1: Mã bất đồng | B1: Hạng mục đối soát | C1: Giá trị ghi nhận cũ | D1: Giá trị chuẩn hóa mới | E1: Căn cứ bằng chứng | F1: Tác động đánh giá & Giải pháp | G1: Trạng thái giải quyết
A2: CONF-01 | B2: Họ của MEM-05 (HE180798) | C2: Trần Xuân Hòa (trong ghi chú audit & commit email) | D2: Tăng Xuân Hòa (Bí danh: Trần Xuân Hòa) | E2: Task_Project_G1_IS2005.xlsx sheet 'Đánh giá thành viên' dòng 4 | F2: Chọn họ Tăng làm chuẩn theo danh sách phân công chính thức; duy trì Trần làm alias để tra cứu lịch sử. | G2: RESOLVED
A3: CONF-02 | B3: Họ của MEM-06 (HE186593) | C3: Phan Thành Vinh (trong ghi chú audit & commit email) | D3: Phạm Thành Vinh (Bí danh: Phan Thành Vinh) | E3: Task_Project_G1_IS2005.xlsx sheet 'Đánh giá thành viên' dòng 7 | F3: Chọn họ Phạm làm chuẩn theo danh sách phân công chính thức; duy trì Phan làm alias để tra cứu lịch sử. | G3: RESOLVED
A4: CONF-03 | B4: Mã số sinh viên (MSSV) của 3 thành viên | C4: UNKNOWN cho Lê Đức Hoàng, Vũ Phương Thảo, Phan Thành Vinh | D4: Khôi phục đầy đủ: HE204568 (Hoàng), HE204054 (Thảo), HE186593 (Vinh) | E4: Task_Project_G1_IS2005.xlsx sheet 'Đánh giá thành viên' | F4: Đầy đủ 100% MSSV cho toàn bộ 6 thành viên; loại bỏ trạng thái UNKNOWN. | G4: RESOLVED
A5: CONF-04 | B5: Quy mô 27 chức năng vs 49 dòng kiểm kê | C5: Báo cáo ghi 27 chức năng; tệp kiểm kê có 49 dòng | D5: Phân định rõ 2 tầng phạm vi: 27 Use Case nghiệp vụ vs 49 cấu phần kỹ thuật | E5: SRS (27 use case nghiệp vụ) vs 04_Module_Completeness.csv (43 module + 6 infra) | F5: Không có mâu thuẫn số học; 27 là phạm vi bài toán người dùng, 49 là phạm vi code deliverables. | G5: RESOLVED
A6: CONF-05 | B6: 6 Sinh viên vs 8 Nhánh tính năng | C6: Tài liệu cũ đôi khi nhắc đến 7 nhánh | D6: Làm rõ chính xác: 6 sinh viên tạo ra 8 nhánh tính năng | E6: Lịch sử Git: DucHoangM1, dat-nguyen-gia, NTDatZB, thao-product, XH, XH4, vinhpt, vinhpt1 | F6: Hòa có 2 nhánh (XH, XH4); Vinh có 2 nhánh (vinhpt, vinhpt1). Tích hợp đầy đủ vào branch chung. | G6: RESOLVED
A7: CONF-06 | B7: Môi trường kiểm thử 536 tests backend | C7: Tuyên bố VERIFIED chung chung không nêu rõ môi trường | D7: Bổ sung đầy đủ ngữ cảnh: 526 pass trên H2 in-memory MSSQLServer mode; 10 bài SQL Server thật bỏ qua | E7: PHASE_5.8.3.117-5.8.3.118_FULL_TEAM_MERGE_HISTORY.txt; pom.xml; application-test.yml | F7: Minh bạch hóa giới hạn kiểm thử: pass 100% logic trên mock/H2, chưa chạy trên SQL Server cluster production. | G7: RESOLVED
A8: CONF-07 | B8: Độ tin cậy của tích hợp cổng thanh toán & SSO | C8: Được gán nhãn HIGH và VERIFIED đồng loạt | D8: Hạ nhãn xuống PARTIALLY_VERIFIED và MEDIUM cho các luồng mạng ngoài | E8: 07_Gap_Register.csv (GAP-01, GAP-02, GAP-08) | F8: Các hàm mã hóa, tính checksum, mock slice đều pass, nhưng live callback chưa thể kích hoạt trong môi trường audit offline. | G8: RESOLVED
A9: CONF-08 | B9: Công thức tính điểm tổng kết thành viên | C9: Tính điểm trung gian qua 4 nhóm tiêu chí làm tròn | D9: Tính trực tiếp bằng SUMPRODUCT từ 11 tiêu chí và trọng số chuẩn | E9: Scoring_Rubric TC-01 đến TC-11; trọng số chuẩn hóa tổng 100.0% | F9: Đồng bộ điểm số 100% trên toàn bộ workbook và các báo cáo (Hoàng: 9.17, G.Đạt: 8.86, T.Đạt: 9.84, Thảo: 9.24, Hòa: 9.09, Vinh: 8.94). | G9: RESOLVED
A10: CONF-09 | B10: Số lượng dòng tác vụ WBS (180 vs 181) | C10: Bảng đối soát có 181 dòng trong khi kế hoạch có 180 tác vụ WBS | D10: Xác định chính xác dòng 185 là dòng ghi chú (NOTE) thời hạn thi cử, không phải tác vụ WBS | E10: Task_Project_G1_IS2005.xlsx dòng 185: NOTE "Thực tế 11/11 là buổi học cuối..." | F10: Giữ nguyên 181 dòng đối soát; định danh rõ dòng 185 là PLANNING_FOOTNOTE / NOT_ASSESSABLE. | G10: RESOLVED
A11: CONF-10 | B11: Phân rã kiểm thử chi tiết (516 vs 526 pass) | C11: Tổng chi tiết M1-M6 + Shared = 516 pass; tổng báo cáo Phase 118 = 526 pass | D11: Ghi nhận độ lệch 10 bài pass là UNRESOLVED_BREAKDOWN_VARIANCE | E11: PHASE_5.8.3.117-5.8.3.118_FULL_TEAM_MERGE_HISTORY.txt (Mục 8.2 chỉ nêu sample suites) | F11: Không tự tạo số liệu kiểm thử; minh bạch hóa khoảng chênh lệch kỹ thuật. | G11: RESOLVED

Sheet Verification_Method
A1: Phương pháp xác minh | B1: Nguồn dữ liệu & Công cụ | C1: Nội dung kiểm tra thực tế | D1: Tiêu chuẩn đạt (Pass Criteria) | E1: Giới hạn & Lưu ý an toàn
